<robot name="diff_robot">
    <link name="base_link">  
    </link>
    <joint name="base_joint" type="fixed">
        <parent link="base_link"/>
        <child link="frame_link"/>
        <origin xyz="-0.05 0.0 0.0" rpy="0.0 0.0 0.0"/>
    </joint>
    <link name="frame_link">
        <visual>
            <geometry>
                <box size="0.15 0.1 0.05"/>
            </geometry>
            <origin xyz="0.075 0.0 0.025" rpy="0.0 0.0 0.0"/>
            <material name="white">
                <color rgba="1.0 0.0 0.0 1.0"/>
            </material>
        </visual>
        <inertial>
            <mass value="4.0"/>
            <origin xyz="0.075 0.0 0.025"/>
            <inertia ixx="0.1" ixy="0.0" ixz="0.0" iyy="0.1" iyz="0.0" izz="0.1"/>
        </inertial>
        <collision>
            <geometry>
                <box size="0.15 0.1 0.05"/>
            </geometry>
            <origin xyz="0.075 0.0 0.025" rpy="0.0 0.0 0.0"/>
        </collision>
    </link>
    <joint name="left_wheel_joint" type="continuous">
        <parent link="base_link"/>
        <child link="left_wheel_link"/>
        <origin xyz="0.0 0.06 0.0" rpy="-1.57 0.0 0.0"/>
        <axis xyz="0.0 0.0 1.0"/>   
    </joint>
    <link name="left_wheel_link">
        <visual>
            <geometry>
                <cylinder radius="0.02" length="0.01"/>
            </geometry>
            <origin xyz="-0.025 0.0 0.0" rpy="0 0.0 0.0"/>
            <material name="blue">
                <color rgba="0.0 0.0 1.0 1.0"/>
            </material>
        </visual>
        <inertial>
            <mass value="1.0"/>
            <origin xyz="0.0 0.0 0.0"/>
            <inertia ixx="0.1" ixy="0.0" ixz="0.0" iyy="0.1" iyz="0.0" izz="0.1"/>
        </inertial>
        <collision>
            <geometry>
                <cylinder radius="0.02" length="0.01"/>
            </geometry>
            <origin xyz="0.0 0.0 0.0" rpy="0 0.0 0.0"/>
        </collision>
    </link>
    <joint name="right_wheel_joint" type="continuous">
        <parent link="base_link"/>
        <child link="right_wheel_link"/>
        <origin xyz="0.0 -0.06 0.0" rpy="1.57 0.0 0.0"/>
        <axis xyz="0.0 0.0 1.0"/>   
    </joint>
    <link name="right_wheel_link">
        <visual>
            <geometry>
                <cylinder radius="0.02" length="0.01"/>
            </geometry>
            <origin xyz="-0.025 0.0 0.0" rpy="0 0.0 0.0"/>
            <material name="blue">
                <color rgba="0.0 0.0 1.0 1.0"/>
            </material>
        </visual>
        <inertial>
            <mass value="1.0"/>
            <origin xyz="0.0 0.0 0.0"/>
            <inertia ixx="0.1" ixy="0.0" ixz="0.0" iyy="0.1" iyz="0.0" izz="0.1"/>
        </inertial>
        <collision>
            <geometry>
                <cylinder radius="0.02" length="0.01"/>
            </geometry>
            <origin xyz="0.0 0.0 0.0" rpy="0 0.0 0.0"/>
        </collision>
    </link>
    <joint name="caster_joint" type="fixed">
        <parent link="base_link"/>
        <child link="caster_link"/>
        <origin xyz="0.075 0.0 0.0"/>        
    </joint>
    <link name="caster_link">
        <visual>
            <geometry>
                <sphere radius="0.02"/>
            </geometry>
            <origin xyz="0.0 0.0 0.0"/>
            <material name="yellow">
                <color rgba="1.0 1.0 0.0 1.0"/>
            </material>
        </visual>
        <inertial>
            <mass value="1e-5"/>
            <origin xyz="0.0 0.0 0.0"/>
            <inertia ixx="1e-6" ixy="0" ixz="0" iyy="1e-6" iyz="0" izz="1e-6"/>
        </inertial>
        <collision>
            <geometry>
                <sphere radius="0.02"/>
            </geometry>
            <origin xyz="0.0 0.0 0.0"/>
        </collision>
    </link>

    <link name="camera_link">
        <visual>
            <geometry>
                <box size="0.01 0.025 0.015"/>
            </geometry>
            <origin xyz="0.07 0.0 0.0475" rpy="0.0 0.0 0.0"/>
            <material name="Purple">
                <color rgba="1.0 0.0 1.0 1.0"/>
            </material>
        </visual>
        <inertial>
            <mass value="1e-5" />
            <origin xyz="0 0 0" rpy="0 0 0"/>
            <inertia ixx="1e-6" ixy="0" ixz="0" iyy="1e-6" iyz="0" izz="1e-6" />
        </inertial>
        <collision>
            <geometry>
                <box size="0.01 0.025 0.015"/>
            </geometry>
            <origin xyz="0.0 0.0 0.0"/>
        </collision>
    </link>
    <joint name="camera_joint" type="fixed">
        <parent link="frame_link"/>
        <child link="camera_link"/>
        <origin xyz="0.09 0.0 0.0" rpy="0.0 0.0 0.0"/>
    </joint>

    <!--Cam bien hokuyo-->
    <link name="hokuyo_link">
        <visual>
            <geometry>
                <cylinder radius="0.02" length="0.02"/>
            </geometry>
            <origin xyz="0.0 0.0 0.0" rpy="0.0 0.0 0.0"/>
            <material name="gray">
                <color rgba="0.5 0.5 0.5 1.0"/>
            </material>
        </visual>
        <inertial>
            <mass value="0.1"/>
            <origin xyz="0.0 0.0 0.0"/>
            <inertia ixx="0.001" ixy="0.0" ixz="0.0" iyy="0.001" iyz="0.0" izz="0.001"/>
        </inertial>
    </link>
    <joint name="hokuyo_joint" type="fixed">
        <parent link="frame_link"/>
        <child link="hokuyo_link"/>
        <origin xyz="0.075 0.0 0.06" rpy="0.0 0.0 0.0"/>
    </joint>

    <!-- Transmission -->
    <transmission name="tran1">
        <type>transmission_interface/SimpleTransmission</type>
        <joint name="left_wheel_joint">
            <hardwareInterface>hardware_interface/EffortJointInterface</hardwareInterface>
        </joint>
        <actuator name="motor1">
            <hardwareInterface>hardware_interface/EffortJointInterface</hardwareInterface>
            <mechanicalReduction>1</mechanicalReduction>
        </actuator>
    </transmission>

    <transmission name="tran2">
        <type>transmission_interface/SimpleTransmission</type>
        <joint name="right_wheel_joint">
            <hardwareInterface>hardware_interface/EffortJointInterface</hardwareInterface>
        </joint>
        <actuator name="motor2">
            <hardwareInterface>hardware_interface/EffortJointInterface</hardwareInterface>
            <mechanicalReduction>1</mechanicalReduction>
        </actuator>
    </transmission>

    <!-- Gazebo -->
    <gazebo reference="frame_link">
        <material>Gazebo/Orange</material>
    </gazebo>
    <gazebo reference="left_wheel_link">
        <material>Gazebo/Blue</material>
    </gazebo>
    <gazebo reference="right_wheel_link">
        <material>Gazebo/Blue</material>
    </gazebo>
    <gazebo reference="caster_link">
        <material>Gazebo/Yellow</material>
    </gazebo>
    <!-- camera -->
    <gazebo reference="camera_link">
        <material>Gazebo/Purple</material>
        <sensor type="camera" name="camera1">
        <update_rate>30.0</update_rate>
        <camera name="head">
            <horizontal_fov>1.3962634</horizontal_fov>
            <image>
                <width>800</width>
                <height>800</height>
                <format>R8G8B8</format>
            </image>
            <clip>
                <near>0.09</near>
                <far>300</far>
            </clip>
            <noise>
            <type>gaussian</type>
                <!-- Noise is sampled independently per pixel on each frame.
                    That pixel's noise value is added to each of its color
                    channels, which at that point lie in the range [0,1]. -->
                <mean>0.0</mean>
                <stddev>0.007</stddev>
            </noise>
        </camera>
        <plugin name="camera_controller" filename="libgazebo_ros_camera.so">
            <alwaysOn>true</alwaysOn>
            <updateRate>0.0</updateRate>
            <cameraName>my_robot/camera1</cameraName>
            <imageTopicName>image_raw</imageTopicName>
            <cameraInfoTopicName>camera_info</cameraInfoTopicName>
            <frameName>camera_link</frameName>
            <hackBaseline>0.07</hackBaseline>
            <distortionK1>0.0</distortionK1>
            <distortionK2>0.0</distortionK2>
            <distortionK3>0.0</distortionK3>
            <distortionT1>0.0</distortionT1>
            <distortionT2>0.0</distortionT2>
        </plugin>
        </sensor>
    </gazebo>
    <!-- Thêm cảm biến Hokuyo -->
    <gazebo reference="hokuyo_link">
        <!-- Các thiết lập khác cho frame_link -->
        <sensor type="ray" name="hokuyo_sensor">
            <pose>0.0 0.0 0.1 0 0 0</pose> <!-- Vị trí và hướng của cảm biến -->
            <visualize>true</visualize> <!-- Hiển thị góc quét trong Gazebo -->
            <update_rate>10</update_rate> <!-- Tần suất cập nhật dữ liệu -->
            <ray>
                <scan>
                    <horizontal>
                        <samples>720</samples> <!-- Số lượng chùm tia quét -->
                        <resolution>1</resolution> <!-- Góc giữa các chùm tia -->
                        <min_angle>-3.14159</min_angle> <!-- Góc bắt đầu của quét -->
                        <max_angle>3.14159</max_angle> <!-- Góc kết thúc của quét -->
                    </horizontal>
                </scan>
                <range>
                    <min>0.1</min> <!-- Khoảng cách tối thiểu -->
                    <max>1.0</max> <!-- Khoảng cách tối đa -->
                    <resolution>0.01</resolution> <!-- Độ phân giải của khoảng cách -->
                </range>
                <noise>
                    <type>gaussian</type>
                    <mean>0.0</mean>
                    <stddev>0.01</stddev>
                </noise>
            </ray>
        </sensor>
    </gazebo>
    <gazebo>
        <plugin name="gazebo_ros_control" filename="libgazebo_ros_control.so">
            <robotNamespace>/my_diffbot</robotNamespace>
        </plugin>
    </gazebo>

</robot>
<!--
rosrun rqt_gui rqt_rui
rosrun turtlesim
rosrun turtlesim turtle_teleop_key
rosrun turtle
rosrun turtlesim
rosrun turtlesim turtlesim_node-->
